<?xml version="1.0" ?>
<!-- =================================================================================== -->
<!-- |    This document was autogenerated by xacro from src/simple_manipulator_moveit_config/config/simple_manipulator.urdf.xacro | -->
<!-- |    EDITING THIS FILE BY HAND IS NOT RECOMMENDED                                 | -->
<!-- =================================================================================== -->
<robot name="simple_manipulator">
  <link name="base_link">
    <visual>
      <geometry>
        <cylinder length="0.2" radius="0.1"/>
      </geometry>
    </visual>
    <collision>
      <geometry>
        <cylinder length="0.2" radius="0.1"/>
      </geometry>
    </collision>
    <inertial>
      <origin rpy="0 0 0" xyz="0 0 0.25"/>
      <mass value="1.0"/>
      <inertia ixx="0.0213" ixy="0.0" ixz="0.0" iyy="0.0213" iyz="0.0" izz="0.001"/>
    </inertial>
  </link>
  <joint name="joint_1" type="revolute">
    <parent link="base_link"/>
    <child link="link_2"/>
    <origin rpy="0 0 0" xyz="0 0 0.1"/>
    <axis xyz="0 0 1"/>
    <limit effort="10.0" lower="-3.14" upper="3.14" velocity="1.0"/>
  </joint>
  <link name="link_2">
    <visual>
      <origin rpy="0 0 0" xyz="0 0 0.25"/>
      <geometry>
        <box size="0.08 0.08 0.5"/>
      </geometry>
    </visual>
    <collision>
      <origin rpy="0 0 0" xyz="0 0 0.25"/>
      <geometry>
        <box size="0.08 0.08 0.5"/>
      </geometry>
    </collision>
    <inertial>
      <origin rpy="0 0 0" xyz="0 0 0.25"/>
      <mass value="1.0"/>
      <inertia ixx="0.0213" ixy="0.0" ixz="0.0" iyy="0.0213" iyz="0.0" izz="0.001"/>
    </inertial>
  </link>
  <joint name="joint_2" type="revolute">
    <parent link="link_2"/>
    <child link="link_3"/>
    <origin rpy="0 0 0" xyz="0 0 0.5"/>
    <axis xyz="0 1 0"/>
    <limit effort="10.0" lower="-1.57" upper="1.57" velocity="1.0"/>
  </joint>
  <link name="link_3">
    <visual>
      <origin rpy="0 0 0" xyz="0 0 0.2"/>
      <geometry>
        <box size="0.06 0.06 0.4"/>
      </geometry>
    </visual>
    <collision>
      <origin rpy="0 0 0" xyz="0 0 0.2"/>
      <geometry>
        <box size="0.06 0.06 0.4"/>
      </geometry>
    </collision>
    <inertial>
      <origin rpy="0 0 0" xyz="0 0 0.25"/>
      <mass value="1.0"/>
      <inertia ixx="0.0213" ixy="0.0" ixz="0.0" iyy="0.0213" iyz="0.0" izz="0.001"/>
    </inertial>
  </link>
  <joint name="gripper_base_joint" type="fixed">
    <parent link="link_3"/>
    <child link="gripper_base"/>
    <origin rpy="0 0 0" xyz="0 0 0.4"/>
  </joint>
  <link name="gripper_base">
    <visual>
      <geometry>
        <box size="0.1 0.04 0.04"/>
      </geometry>
    </visual>
    <collision>
      <geometry>
        <box size="0.1 0.04 0.04"/>
      </geometry>
    </collision>
    <inertial>
      <origin rpy="0 0 0" xyz="0 0 0.25"/>
      <mass value="1.0"/>
      <inertia ixx="0.0213" ixy="0.0" ixz="0.0" iyy="0.0213" iyz="0.0" izz="0.001"/>
    </inertial>
  </link>
  <joint name="left_gripper_joint" type="prismatic">
    <parent link="gripper_base"/>
    <child link="left_gripper_jaw"/>
    <origin rpy="0 0 0" xyz="-0.04 0 0.02"/>
    <axis xyz="1 0 0"/>
    <limit effort="5.0" lower="0.0" upper="0.03" velocity="0.5"/>
  </joint>
  <link name="left_gripper_jaw">
    <visual>
      <origin rpy="0 0 0" xyz="0 0 0.03"/>
      <geometry>
        <box size="0.01 0.02 0.06"/>
      </geometry>
    </visual>
    <collision>
      <origin rpy="0 0 0" xyz="0 0 0.03"/>
      <geometry>
        <box size="0.01 0.02 0.06"/>
      </geometry>
    </collision>
    <inertial>
      <origin rpy="0 0 0" xyz="0 0 0.25"/>
      <mass value="1.0"/>
      <inertia ixx="0.0213" ixy="0.0" ixz="0.0" iyy="0.0213" iyz="0.0" izz="0.001"/>
    </inertial>
  </link>
  <ros2_control name="FakeSystem" type="system">
    <hardware>
      <!-- By default, set up controllers for simulation. This won't work on real hardware -->
      <plugin>gz_ros2_control/GazeboSimSystem</plugin>
    </hardware>
    <joint name="joint_1">
      <command_interface name="position"/>
      <state_interface name="position">
        <param name="initial_value">0</param>
      </state_interface>
      <state_interface name="velocity"/>
    </joint>
    <joint name="joint_2">
      <command_interface name="position"/>
      <state_interface name="position">
        <param name="initial_value">0</param>
      </state_interface>
      <state_interface name="velocity"/>
    </joint>
    <joint name="left_gripper_joint">
      <command_interface name="position"/>
      <state_interface name="position">
        <param name="initial_value">0</param>
      </state_interface>
      <state_interface name="velocity"/>
    </joint>
  </ros2_control>
  <gazebo>
    <plugin filename="libgz_ros2_control-system.so" name="gz_ros2_control::GazeboSimROS2ControlPlugin">
      <parameters>/home/user/ros2_ws/install/simple_manipulator_moveit_config/share/simple_manipulator_moveit_config/config/ros2_controllers.yaml</parameters>
      <controller_manager_name>controller_manager</controller_manager_name>
    </plugin>
  </gazebo>
</robot>
